Workbook

Sheet sheet1
A1: Property ID | B1: UPRN | C1: No Range | D1: Building Name | E1: Street No | F1: Street | G1: Town | H1: Pcode | I1: External - can you access via a trade button or intercom? | J1: External - what times are they available or any other information? | K1: External - is a fire brigade drop switch available? | L1: External - what type of key | M1: Internal - is a fob or key required? | N1: Internal - what type of key | O1: Internal - Add a description if needed | P1: Internal - is a key code required? | Q1: Contact | R1: Contact Confirmed | S1: Contact email | T1: Primary Contact Number | U1: Secondary Contact Number | V1: Notes | W1: Other Possible Contact Details | Z1: Other Possible Contact Details
A2: 4209 | B2: ACTO0023 | C2: A-C | E2: 23 | F2: Acton Lane | G2: London | H2: NW10 8UX | I2: No | K2: No | M2: Yes | N2: FB key | O2: FB2 | P2: No | Z2: =_xlfn.LET(_xlpm.result,VLOOKUP(B2,FurtherContactDetails!$A$1:$B$1803,2,FALSE), _xlfn.IFNA(IF(_xlpm.result=0,"",_xlpm.result),""))
A3: 4210 | B3: ACTO0035 | C3: A-B | E3: 35 | F3: Acton Lane | G3: London | H3: NW10 8UX | I3: No | K3: No | M3: Yes | N3: FB key | O3: Meter Key | P3: No | Z3: =_xlfn.LET(_xlpm.result,VLOOKUP(B3,FurtherContactDetails!$A$1:$B$1803,2,FALSE), _xlfn.IFNA(IF(_xlpm.result=0,"",_xlpm.result),""))
A4: 14314 | B4: AIRC0001 | C4: 1-29 | F4: Airco Close | G4: London | H4: NW9 0NW | I4: Yes | K4: Yes | L4: Drop key | M4: Yes | N4: FB key | O4: FB2 for service cupboards, T Bar for false ceiling hatches, drop key for open balcony access | P4: No | Q4: Amarjit Gujral | S4: amarjit@apnaghar.org.uk | T4: 02037645082 | U4: 07920776348 | Z4: =_xlfn.LET(_xlpm.result,VLOOKUP(B4,FurtherContactDetails!$A$1:$B$1803,2,FALSE), _xlfn.IFNA(IF(_xlpm.result=0,"",_xlpm.result),""))
A5: 14315 | B5: AIRC0105 | C5: 105-128 | F5: Airco Close | G5: London | H5: NW9 0NX | I5: Yes | K5: Yes | L5: Drop key | M5: Yes | N5: FB key | O5: FB1&2 for service risers, drop key for balcony access | P5: No | Q5: Amarjit Gujral | S5: amarjit@apnaghar.org.uk | T5: 02037645082 | U5: 07920776348 | Z5: =_xlfn.LET(_xlpm.result,VLOOKUP(B5,FurtherContactDetails!$A$1:$B$1803,2,FALSE), _xlfn.IFNA(IF(_xlpm.result=0,"",_xlpm.result),""))
A6: 4212 | B6: ANSO0041 | C6: A-C | E6: 41 | F6: Anson Road | G6: London | H6: NW2 3UY | I6: Yes | K6: No | M6: Yes | N6: FB key | O6: Meter Key | P6: No | Z6: =_xlfn.LET(_xlpm.result,VLOOKUP(B6,FurtherContactDetails!$A$1:$B$1803,2,FALSE), _xlfn.IFNA(IF(_xlpm.result=0,"",_xlpm.result),""))
A7: 73572 | B7: ARAG0000 | C7: 1-6 | D7: Aragon Court | F7: Welwyn Road | G7: Hertford | H7: SG14 2FE | I7: Yes | J7: Intercom only | K7: No | M7: Yes | N7: FB key | O7: FB2 | P7: No | Z7: =_xlfn.LET(_xlpm.result,VLOOKUP(B7,FurtherContactDetails!$A$1:$B$1803,2,FALSE), _xlfn.IFNA(IF(_xlpm.result=0,"",_xlpm.result),""))
A8: 4962 | B8: BALM0027 | C8: A-B | E8: 27 | F8: Balmoral Road | G8: London | H8: NW2 5DU | I8: Yes | J8: Intercom Only | K8: No | M8: Yes | N8: FB key | O8: Meter key | P8: No | Z8: =_xlfn.LET(_xlpm.result,VLOOKUP(B8,FurtherContactDetails!$A$1:$B$1803,2,FALSE), _xlfn.IFNA(IF(_xlpm.result=0,"",_xlpm.result),""))
A9: 33362 | B9: BLAN0000-2 | C9: 29-45 | D9: Blanche Court | F9: Rectory Park Avenue | G9: Southall | H9: UB5 6HG | I9: Yes | J9: Intercom is provided to flats. Trade times are unknown. Entry can also be gained by a key fob. | K9: Yes | L9: Drop key | M9: Yes | N9: FB key | P9: No | Q9: Michael Smith | T9: 02084381061 | Z9: =_xlfn.LET(_xlpm.result,VLOOKUP(B9,FurtherContactDetails!$A$1:$B$1803,2,FALSE), _xlfn.IFNA(IF(_xlpm.result=0,"",_xlpm.result),""))
A10: 8292 | B10: BLEN0061 | C10: A-B | E10: 61 | F10: Blenheim Gardens | G10: London | H10: NW2 4NR | I10: Yes | K10: No | M10: Yes | N10: FB key | P10: No | Z10: =_xlfn.LET(_xlpm.result,VLOOKUP(B10,FurtherContactDetails!$A$1:$B$1803,2,FALSE), _xlfn.IFNA(IF(_xlpm.result=0,"",_xlpm.result),""))
A11: 77061 | B11: ACAD0118 | C11: 118-128 | F11: Academy Way | G11: Loughton, Essex | H11: IG10 3GY | I11: Yes | J11: Intercom is provided to flats. Trade times are unknown. Entry can also be gained by a key fob. | K11: Yes | L11: Drop key | M11: Yes | N11: Fob key | P11: No | Z11: =_xlfn.LET(_xlpm.result,VLOOKUP(B11,FurtherContactDetails!$A$1:$B$1803,2,FALSE), _xlfn.IFNA(IF(_xlpm.result=0,"",_xlpm.result),""))
A12: 4335 | B12: ACAI0000 | C12: 1-32 | D12: Acacia Court | F12: Apline Road | G12: London | H12: NW9 9BP | I12: Yes | J12: Intercom available, no trades | K12: No | M12: Yes | N12: Fob key | O12: Fob required for basement and upper floor flat lobbies | P12: Yes | Z12: =_xlfn.LET(_xlpm.result,VLOOKUP(B12,FurtherContactDetails!$A$1:$B$1803,2,FALSE), _xlfn.IFNA(IF(_xlpm.result=0,"",_xlpm.result),""))
A13: 77407 | B13: AGAE0000-1 | C13: 1-73 | D13: Agate Heights | E13: 98B | F13: Burnt Oak Broadway | G13: Barnet | H13: HA8 0FW | I13: Yes | J13: intercom to flats | K13: Yes | L13: Gerda key | M13: Yes | N13: Fob key | O13: KMS fob required | P13: Yes | Q13: Sayeed Ali | R13: 46169.607 | S13: Sayeed.Ali@sng.org.uk | T13: 07825 931393 | U13: 0204 512 5802 | V13: Contact - Estate.Services-London@sng.org.uk - for access | W13: Rukayat Soaga - 07387 525166 | Z13: =_xlfn.LET(_xlpm.result,VLOOKUP(B13,FurtherContactDetails!$A$1:$B$1803,2,FALSE), _xlfn.IFNA(IF(_xlpm.result=0,"",_xlpm.result),"")) -> Rukayat Soaga - 07387 525166
A14: 78669 | B14: AMET0000 | C14: 1-21 | D14: Amethyst Court | E14: 6 | F14: Woodlands Avenue | G14: London | H14: W3 9DZ | I14: Yes | J14: Intercom to flats | K14: Yes | L14: Drop key | M14: Yes | N14: Fob key | P14: No | W14: Rukayat Soaga - 07387 525166 | Z14: =_xlfn.LET(_xlpm.result,VLOOKUP(B14,FurtherContactDetails!$A$1:$B$1803,2,FALSE), _xlfn.IFNA(IF(_xlpm.result=0,"",_xlpm.result),"")) -> Rukayat Soaga - 07387 525166
A15: 13293 | B15: ARGU0000-2 | C15: 19-36 | D15: Argus Court | E15: 4 | F15: Guardian Avenue | G15: Edgware | H15: NW9 4BE | I15: Yes | J15: Intercom only. | K15: Yes | L15: Drop key | M15: Yes | N15: Fob key | O15: Intratone Fob. | P15: No | Z15: =_xlfn.LET(_xlpm.result,VLOOKUP(B15,FurtherContactDetails!$A$1:$B$1803,2,FALSE), _xlfn.IFNA(IF(_xlpm.result=0,"",_xlpm.result),""))
A16: 66276 | B16: ARLI0000-CP | D16: Arlidge House Car Park | E16: 11-14 | F16: Kirby Street | G16: London | H16: EC1N 8TW | I16: No | K16: Yes | L16: Drop key | M16: Yes | N16: Fob key | O16: PAC Fob | Z16: =_xlfn.LET(_xlpm.result,VLOOKUP(B16,FurtherContactDetails!$A$1:$B$1803,2,FALSE), _xlfn.IFNA(IF(_xlpm.result=0,"",_xlpm.result),""))
A17: 4207 | B17: AURO0000 | C17: 1-62 | D17: Aurora House | F17: Central Way | G17: London | H17: NW10 7FN | M17: Yes | N17: Fob key | O17: Intratone fob. | P17: Yes | Q17: Hemal Ramtale​ | R17: 46218.582 | S17: hemal.ramtale@networkhomes.org.uk | T17: 0792 087 7554 | V17: hemal.ramtale@networkhomes.org.uk | W17: Samuel Drinkwater - 0204 512 5948 | Z17: =_xlfn.LET(_xlpm.result,VLOOKUP(B17,FurtherContactDetails!$A$1:$B$1803,2,FALSE), _xlfn.IFNA(IF(_xlpm.result=0,"",_xlpm.result),"")) -> Samuel Drinkwater - 0204 512 5948
A18: 9089 | B18: AYLS0000 | C18: 2-89 | D18: Aylesbury House | F18: Hatton Road | G18: Wembley | H18: HA0 1QW | I18: Yes | J18: Intercom to flats (no trade button) | K18: No | M18: Yes | N18: Fob key | O18: Collect from concierge in Venice House | P18: No | Q18: Security Office | R18: 46038.454 | S18: 243ealingroad@networkhomes.org.uk | T18: 2089976822 | U18: 7741744603 | W18: Nargis Khan - 07385952920 | Z18: =_xlfn.LET(_xlpm.result,VLOOKUP(B18,FurtherContactDetails!$A$1:$B$1803,2,FALSE), _xlfn.IFNA(IF(_xlpm.result=0,"",_xlpm.result),"")) -> Nargis Khan - 07385952920
A19: 77320 | B19: AYTO0015 | C19: 1-20 | E19: 15 | F19: Aytoun Road | G19: London | H19: SW9 0TT | I19: Yes | J19: Intercom | K19: Yes | L19: Crescent key | M19: Yes | N19: Fob key | O19: collect from 25 Robsart Street Concierge. | P19: No | Z19: =_xlfn.LET(_xlpm.result,VLOOKUP(B19,FurtherContactDetails!$A$1:$B$1803,2,FALSE), _xlfn.IFNA(IF(_xlpm.result=0,"",_xlpm.result),""))
A20: 13854 | B20: BARR0010 | C20: 10-18 | D20: Barrie Court | E20: 30 | F20: Lyonsdown Road | G20: London | H20: EN5 1HZ | I20: Yes | J20: 7am 2pm | K20: No | M20: Yes | N20: Fob key | P20: No | Z20: =_xlfn.LET(_xlpm.result,VLOOKUP(B20,FurtherContactDetails!$A$1:$B$1803,2,FALSE), _xlfn.IFNA(IF(_xlpm.result=0,"",_xlpm.result),""))
A21: 38382 | B21: BENE0001 | C21: 1-33 | D21: Thrayle House | E21: 1 | F21: Benedict Road | G21: London | H21: SW9 0FR | I21: Yes | J21: Intercom is provided to flats. Entry can also be gained by a key fob. No Trade button. | K21: No | M21: Yes | N21: Fob key | O21: fob and non Standard keys for Cads | P21: No | Q21: Sajjad Ashraf | R21: 46105.673 | S21: sajjad.ashraf@sw9.org.uk | T21: 2046043187 | V21: separate FRA conducted on shared carpark BENE0009-CP, Shared Residential Car Park - Benedict Road, 9 Benedict Road Car Park, London, SW9 0FS | W21: Shane S. Simpson - 07345 222 959 | Z21: =_xlfn.LET(_xlpm.result,VLOOKUP(B21,FurtherContactDetails!$A$1:$B$1803,2,FALSE), _xlfn.IFNA(IF(_xlpm.result=0,"",_xlpm.result),"")) -> Shane S. Simpson - 07345 222 959
A22: 39602 | B22: BENE0009-CP | D22: Shared Residential Car Park - Benedict Road | E22: 9 | F22: Benedict Road Car Park | G22: London | H22: SW9 0FS | I22: No | K22: No | M22: Yes | N22: Fob key | O22: collect from concierge | P22: No | Z22: =_xlfn.LET(_xlpm.result,VLOOKUP(B22,FurtherContactDetails!$A$1:$B$1803,2,FALSE), _xlfn.IFNA(IF(_xlpm.result=0,"",_xlpm.result),""))
A23: 4972 | B23: BEST0000 | C23: 1-31 | D23: Best House | F23: Matthews Close | G23: Wembley | H23: HA9 8FE | I23: No | K23: Yes | L23: Drop key | M23: Yes | N23: Fob key | O23: Intratone. | P23: No | W23: Sharon Salmon - 07345 222 965 | Z23: =_xlfn.LET(_xlpm.result,VLOOKUP(B23,FurtherContactDetails!$A$1:$B$1803,2,FALSE), _xlfn.IFNA(IF(_xlpm.result=0,"",_xlpm.result),"")) -> Sharon Salmon - 07345 222 965
A24: 77408 | B24: BISM0000 | C24: 1-28 | D24: Bismuth Heights | E24: 100 | F24: Burnt Oak Broadway | G24: Barnet | H24: HA8 0FX | I24: Yes | J24: Intercom is provided to the flats | K24: No | M24: Yes | N24: Fob key | P24: No | Q24: Samuel Babalola | R24: 46132.503 | S24: Samuel.Babalola@sng.org.uk | T24: 0207 326 3720 | W24: Rukayat Soaga - 07387 525166 | Z24: =_xlfn.LET(_xlpm.result,VLOOKUP(B24,FurtherContactDetails!$A$1:$B$1803,2,FALSE), _xlfn.IFNA(IF(_xlpm.result=0,"",_xlpm.result),"")) -> Rukayat Soaga - 07387 525166
A25: 32981 | B25: BLAN0000-1 | C25: 1-28 | D25: Blanche Court | F25: Rectory Park Avenue | G25: Southall | H25: UB5 6HG | I25: Yes | J25: Intercom is provided to the flats. | K25: Yes | L25: Drop key | M25: Yes | N25: Fob key | O25: Intratone Fob required for bin room and cycle store. | P25: No | Q25: Michael Smith | R25: 46105.673 | T25: 02084381061 | Z25: =_xlfn.LET(_xlpm.result,VLOOKUP(B25,FurtherContactDetails!$A$1:$B$1803,2,FALSE), _xlfn.IFNA(IF(_xlpm.result=0,"",_xlpm.result),""))
A26: 4332 | B26: BRAU0000 | C26: 1-77 | D26: Braunston House | F26: Hatton Road | G26: London | H26: HA0 1RP | I26: Yes | J26: Intercom to flats (no trade button). | K26: Yes | L26: Drop key | M26: Yes | N26: Fob key | O26: Collect from concierge Venice House | P26: No | Q26: Security Office | R26: 46038.454 | S26: 243ealingroad@networkhomes.org.uk | T26: 2089976822 | U26: 7741744603 | W26: Sharon Salmon - 07345 222 965 | Z26: =_xlfn.LET(_xlpm.result,VLOOKUP(B26,FurtherContactDetails!$A$1:$B$1803,2,FALSE), _xlfn.IFNA(IF(_xlpm.result=0,"",_xlpm.result),"")) -> Sharon Salmon - 07345 222 965
A27: 44521 | B27: 2327030000 | D27: Community Hall | F27: Folly View | G27: Ware | H27: SG12 8AY | I27: No | K27: No | M27: Yes | N27: Master key | O27: Codes - 0836 - External key safe. 1970 - Contractors key safe | P27: Yes | Q27: Debbie Gurrin | S27: debbie.gurrin@networkhomes.org.uk | T27: 07899922581 | U27: 01992501678 | Z27: =_xlfn.LET(_xlpm.result,VLOOKUP(B27,FurtherContactDetails!$A$1:$B$1803,2,FALSE), _xlfn.IFNA(IF(_xlpm.result=0,"",_xlpm.result),""))
A28: 14367 | B28: AIRC0077 | C28: 76-99 | F28: Airco Close | G28: London | H28: NW9 0NX | I28: Yes | J28: Intercom is provided to flats. Trade times are unknown. Entry can also be gained by a key fob. | M28: Yes | N28: Master key | O28: Key to be collected from Innisfree Housing Association Ltd, 190 Iverson Road, London, NW6 2HL | Q28: Amarjit Gujral | S28: amarjit@apnaghar.org.uk | T28: 02037645082 | U28: 07920776348 | Z28: =_xlfn.LET(_xlpm.result,VLOOKUP(B28,FurtherContactDetails!$A$1:$B$1803,2,FALSE), _xlfn.IFNA(IF(_xlpm.result=0,"",_xlpm.result),""))
A29: 79798 | B29: AMA0000 | C29: 1-74 | D29: Amour Court | E29: 4A | F29: Central Way | G29: London | H29: NW10 7RW | I29: Yes | J29: Intercom to Flats only, no Trade button. | K29: No | M29: Yes | N29: Master key | O29: KMS required for Building Entry & Stairwell. Master Keys required for Riser Cupboards. | P29: No | Q29: Marlon Jagdeo | R29: 45744.453 | S29: marlon.jagdeo@barnardmarcus.co.uk | T29: 020 8579 5050 | U29: 07860381463 | W29: Rukayat Soaga - 07387 525166 | Z29: =_xlfn.LET(_xlpm.result,VLOOKUP(B29,FurtherContactDetails!$A$1:$B$1803,2,FALSE), _xlfn.IFNA(IF(_xlpm.result=0,"",_xlpm.result),"")) -> Rukayat Soaga - 07387 525166
A30: 44882 | B30: ANNA0000 | C30: 1-11 | D30: Anna Court | F30: The Ridgeway | G30: Hertford | H30: SG14 2TL | I30: Yes | J30: Intercom available, no trades | K30: No | M30: Yes | N30: Master key | O30: Non standard key for risers. | P30: No | Z30: =_xlfn.LET(_xlpm.result,VLOOKUP(B30,FurtherContactDetails!$A$1:$B$1803,2,FALSE), _xlfn.IFNA(IF(_xlpm.result=0,"",_xlpm.result),""))
A31: 13839 | B31: ASHM0121 | C31: A-C | E31: 121 | F31: Ashmore Road | G31: London | H31: W9 3DA | I31: No | K31: No | M31: Yes | N31: Master key | P31: No | Z31: =_xlfn.LET(_xlpm.result,VLOOKUP(B31,FurtherContactDetails!$A$1:$B$1803,2,FALSE), _xlfn.IFNA(IF(_xlpm.result=0,"",_xlpm.result),""))
A32: 2747 | B32: ASHM0122 | C32: A-C | E32: 122 | F32: Ashmore Road | G32: London | H32: W9 3DQ | I32: Yes | J32: Intercom to the flats. No trade button. | K32: No | M32: Yes | N32: Master key | P32: No | Z32: =_xlfn.LET(_xlpm.result,VLOOKUP(B32,FurtherContactDetails!$A$1:$B$1803,2,FALSE), _xlfn.IFNA(IF(_xlpm.result=0,"",_xlpm.result),""))
A33: 13841 | B33: ASHM0125 | C33: A-C | E33: 125 | F33: Ashmore Road | G33: London | H33: W9 3DA | I33: No | K33: No | M33: Yes | N33: Master key | P33: No | Z33: =_xlfn.LET(_xlpm.result,VLOOKUP(B33,FurtherContactDetails!$A$1:$B$1803,2,FALSE), _xlfn.IFNA(IF(_xlpm.result=0,"",_xlpm.result),""))
A34: 13842 | B34: ASHM0137 | C34: A-C | E34: 137 | F34: Ashmore Road | G34: London | H34: W9 3DA | I34: Yes | J34: daytime | K34: No | M34: Yes | N34: Master key | P34: No | Z34: =_xlfn.LET(_xlpm.result,VLOOKUP(B34,FurtherContactDetails!$A$1:$B$1803,2,FALSE), _xlfn.IFNA(IF(_xlpm.result=0,"",_xlpm.result),""))
A35: 13847 | B35: ASHM0161 | C35: A-B | E35: 161 | F35: Ashmore Road | G35: London | H35: W9 3DA | I35: Yes | J35: daytime | K35: No | M35: Yes | N35: Master key | P35: No | Z35: =_xlfn.LET(_xlpm.result,VLOOKUP(B35,FurtherContactDetails!$A$1:$B$1803,2,FALSE), _xlfn.IFNA(IF(_xlpm.result=0,"",_xlpm.result),""))
A36: 4588 | B36: ASHM0242 | C36: A-C | E36: 242 | F36: Ashmore Road | G36: London | H36: W9 3DD | I36: No | K36: No | M36: Yes | N36: Master key | P36: No | Z36: =_xlfn.LET(_xlpm.result,VLOOKUP(B36,FurtherContactDetails!$A$1:$B$1803,2,FALSE), _xlfn.IFNA(IF(_xlpm.result=0,"",_xlpm.result),""))
A37: 8918 | B37: ATRI0001 | D37: Atrium Point | F37: Greenford Road | G37: Greenford | H37: UB6 0FF | I37: Yes | J37: Intercom is provided to flats and the concierge.Barrier at the entrance to the territory code:1234# | K37: Yes | L37: Drop key | M37: Yes | N37: Master key | O37: Required to access the flats. | P37: No | W37: Nargis Khan - 07385952920 | Z37: =_xlfn.LET(_xlpm.result,VLOOKUP(B37,FurtherContactDetails!$A$1:$B$1803,2,FALSE), _xlfn.IFNA(IF(_xlpm.result=0,"",_xlpm.result),"")) -> Nargis Khan - 07385952920
A38: 3641 | B38: AVER0001 | C38: 1-140 | D38: Avery Court | E38: 40, 41 & 45 | F38: Capitol Way | G38: London | H38: NW9 0AU | I38: Yes | J38: unknown | K38: Yes | L38: Drop key | M38: Yes | N38: Master key | O38: collect fob from Everly House | P38: No | Q38: Security Office | R38: 46038.455 | S38: 243ealingroad@networkhomes.org.uk | T38: 2089976822 | U38: 7741744603 | W38: Rukayat Soaga - 07387 525166 | Z38: =_xlfn.LET(_xlpm.result,VLOOKUP(B38,FurtherContactDetails!$A$1:$B$1803,2,FALSE), _xlfn.IFNA(IF(_xlpm.result=0,"",_xlpm.result),"")) -> Rukayat Soaga - 07387 525166
A39: 4217 | B39: BARD0000-1 | C39: 1-8 | D39: Barnard House | F39: Brenthouse Road | G39: London | H39: E9 6QN | I39: Yes | J39: intercom to flats | K39: Yes | L39: Drop key | M39: Yes | N39: Master key | O39: Collect from office block 1-8 Room D | P39: No | Q39: Kris Vadher | R39: 46218.582 | T39: 07769931222 | V39: Project Manager | Z39: =_xlfn.LET(_xlpm.result,VLOOKUP(B39,FurtherContactDetails!$A$1:$B$1803,2,FALSE), _xlfn.IFNA(IF(_xlpm.result=0,"",_xlpm.result),""))
A40: 6453 | B40: BARD0000-2 | C40: 9-16 | D40: Barnard House | F40: Brenthouse Road | G40: London | H40: E9 6QN | I40: Yes | J40: intercom to flats | K40: Yes | L40: Drop key | M40: Yes | N40: Master key | O40: collect key from block 1-8 room D | P40: No | Q40: Kris Vadher | R40: 46218.582 | T40: 07769931222 | V40: Project Manager | Z40: =_xlfn.LET(_xlpm.result,VLOOKUP(B40,FurtherContactDetails!$A$1:$B$1803,2,FALSE), _xlfn.IFNA(IF(_xlpm.result=0,"",_xlpm.result),""))
...

Sheet FurtherContactDetails
A1: Customer Building Reference Code | B1: BSO name/ mobile
A2: RAIB0001 | B2: Nargis Khan - 07385952920
A3: OXFO0000 | B3: Richard Brown - 0208 459 9237
A4: AMET0000 | B4: Rukayat Soaga - 07387 525166
A5: ASTL0000 | B5: Sharon Salmon - 07345 222 965
A6: LANG0000 | B6: Richard Brown - 0208 459 9237
A7: PRIC0000 | B7: Richard Brown - 0208 459 9237
A8: BOTA0000 | B8: Nargis Khan - 07385952920
A9: ATRI0001 | B9: Nargis Khan - 07385952920
A10: LARK0002 | B10: Nargis Khan - 07385952920
A11: ULEX0000 | B11: Adam Farah - 07471813617
A12: LINI0000 | B12: Nargis Khan - 07385952920
... A22: ROBA0011 | B22: Shane S. Simpson - 07345 222 959
A23: BURN0000
A24: DOUG0000 | B24: Shane S. Simpson - 07345 222 959
A25: COBB0009
A26: COBB0027
A27: MORI0000 | B27: Shane S. Simpson - 07345 222 959
A28: WILB0007 | B28: Shane S. Simpson - 07345 222 959
A29: HENR0000 | B29: Adam Farah - 07471813617
A30: BREE0000 | B30: Rukayat Soaga - 07387 525166
A31: AVER0001 | B31: Rukayat Soaga - 07387 525166
A32: HANS0015 | B32: Richard Brown - 0208 459 9237
A33: CAMD0082 | B33: Richard Brown - 0208 459 9237
A34: CAMD0072 | B34: Richard Brown - 0208 459 9237
A35: ELEC0000 | B35: Rukayat Soaga - 07387 525166
A36: NAY0000 | B36: Rukayat Soaga - 07387 525166
A37: AMA0000 | B37: Rukayat Soaga - 07387 525166
A38: LEI0000 | B38: Rukayat Soaga - 07387 525166
... A79: COMP0000 | B79: Samuel Drinkwater - 0204 512 5948
A80: ARCT0000
A81: CAMD0074 | B81: Richard
A82: WARR0037 | B82: Richard Brown - 0208 459 9237
A83: WARR0039 | B83: Richard Brown - 0208 459 9237
A84: SUTH0180 | B84: Richard Brown - 0208 459 9237
A85: MAAD0000 | B85: Richard Brown - 0208 459 9237
A86: HIND0000 | B86: Shane S. Simpson - 07345 222 959
A87: EAGE0000 | B87: Adam
A88: LANG0000-CP | B88: Richard Brown - 0208 459 9237
A89: HANL0093
...
